<?xml version="1.0" ?>
<!-- =================================================================================== -->
<!-- |    This document was autogenerated by xacro from /home/sroite/ros/agent_system_ws/src/buer/models/buer.xacro | -->
<!-- |    EDITING THIS FILE BY HAND IS NOT RECOMMENDED                                 | -->
<!-- =================================================================================== -->
<robot name="buer">
  <!-- Base link -->
  <link name="head">
    <visual>
      <geometry>
        <mesh filename="stl/head.stl" scale="0.0004 0.0004 0.0004"/>
      </geometry>
    </visual>
    <collision>
      <geometry>
        <cylinder length="0.0004" radius="0.0004"/>
      </geometry>
    </collision>
    <inertial>
      <origin rpy="0 0 0" xyz="0 0 0"/>
      <mass value="8.0"/>
      <inertia ixx="1.5" ixy="0" ixz="0" iyy="1.5" iyz="0" izz="2.0"/>
    </inertial>
    <sensor name="imu" type="imu">
      <origin rpy="0 0 0" xyz="0 0 0"/>
    </sensor>
  </link>
  <link name="leg1_lap">
    <visual>
      <geometry>
        <mesh filename="stl/lap.stl" scale="0.0004 0.0004 0.0004"/>
      </geometry>
    </visual>
    <collision>
      <geometry>
        <mesh filename="stl/lap.stl" scale="0.0004 0.0004 0.0004"/>
      </geometry>
    </collision>
    <inertial>
      <origin rpy="0 0 0" xyz="0.0 0.0 0.0002"/>
      <mass value="1.2"/>
      <inertia ixx="0.08" ixy="0" ixz="0" iyy="0.08" iyz="0" izz="0.01"/>
    </inertial>
  </link>
  <joint name="leg1_lap_joint" type="revolute">
    <parent link="head"/>
    <child link="leg1_lap"/>
    <origin rpy="-1.57 0 0" xyz="0.0 0.22022112000000002 0.0"/>
    <axis xyz="1 0 0"/>
    <limit effort="100.0" lower="-0.5" upper="0.5" velocity="10.0"/>
  </joint>
  <link name="leg1_calf">
    <visual>
      <geometry>
        <mesh filename="stl/calf.stl" scale="0.0004 0.0004 0.0004"/>
      </geometry>
    </visual>
    <collision>
      <geometry>
        <mesh filename="stl/calf.stl" scale="0.0004 0.0004 0.0004"/>
      </geometry>
    </collision>
    <inertial>
      <origin rpy="0 0 0" xyz="0.0 0.0 0.00016"/>
      <mass value="0.8"/>
      <inertia ixx="0.04" ixy="0" ixz="0" iyy="0.04" iyz="0" izz="0.005"/>
    </inertial>
  </link>
  <joint name="leg1_calf_joint" type="revolute">
    <parent link="leg1_lap"/>
    <child link="leg1_calf"/>
    <origin rpy="0 0 1.5708" xyz="0.0 0.0 0.4"/>
    <axis xyz="1 0 0"/>
    <limit effort="100.0" lower="-2.0" upper="2.0" velocity="10.0"/>
  </joint>
  <link name="leg1_foot">
    <visual>
      <geometry>
        <mesh filename="stl/foot.stl" scale="0.0004 0.0004 0.0004"/>
      </geometry>
    </visual>
    <collision>
      <geometry>
        <mesh filename="stl/foot.stl" scale="0.0004 0.0004 0.0004"/>
      </geometry>
    </collision>
    <inertial>
      <origin rpy="0 0 0" xyz="0.0 0.0 0.0"/>
      <mass value="0.5"/>
      <inertia ixx="0.02" ixy="0" ixz="0" iyy="0.02" iyz="0" izz="0.002"/>
    </inertial>
  </link>
  <joint name="leg1_foot_joint" type="revolute">
    <parent link="leg1_calf"/>
    <child link="leg1_foot"/>
    <origin rpy="0 0 0" xyz="0.0 0.0 0.32"/>
    <axis xyz="1 0 0"/>
    <limit effort="100.0" lower="-2.0" upper="2.0" velocity="10.0"/>
  </joint>
  <link name="leg2_lap">
    <visual>
      <geometry>
        <mesh filename="stl/lap.stl" scale="0.0004 0.0004 0.0004"/>
      </geometry>
    </visual>
    <collision>
      <geometry>
        <mesh filename="stl/lap.stl" scale="0.0004 0.0004 0.0004"/>
      </geometry>
    </collision>
    <inertial>
      <origin rpy="0 0 0" xyz="0.0 0.0 0.0002"/>
      <mass value="1.2"/>
      <inertia ixx="0.08" ixy="0" ixz="0" iyy="0.08" iyz="0" izz="0.01"/>
    </inertial>
  </link>
  <joint name="leg2_lap_joint" type="revolute">
    <parent link="head"/>
    <child link="leg2_lap"/>
    <origin rpy="-1.57 0 -1.257" xyz="0.20944000000000002 0.06804 0.0"/>
    <axis xyz="1 0 0"/>
    <limit effort="100.0" lower="-0.5" upper="0.5" velocity="10.0"/>
  </joint>
  <link name="leg2_calf">
    <visual>
      <geometry>
        <mesh filename="stl/calf.stl" scale="0.0004 0.0004 0.0004"/>
      </geometry>
    </visual>
    <collision>
      <geometry>
        <mesh filename="stl/calf.stl" scale="0.0004 0.0004 0.0004"/>
      </geometry>
    </collision>
    <inertial>
      <origin rpy="0 0 0" xyz="0.0 0.0 0.00016"/>
      <mass value="0.8"/>
      <inertia ixx="0.04" ixy="0" ixz="0" iyy="0.04" iyz="0" izz="0.005"/>
    </inertial>
  </link>
  <joint name="leg2_calf_joint" type="revolute">
    <parent link="leg2_lap"/>
    <child link="leg2_calf"/>
    <origin rpy="0 0 1.5708" xyz="0.0 0.0 0.4"/>
    <axis xyz="1 0 0"/>
    <limit effort="100.0" lower="-2.0" upper="2.0" velocity="10.0"/>
  </joint>
  <link name="leg2_foot">
    <visual>
      <geometry>
        <mesh filename="stl/foot.stl" scale="0.0004 0.0004 0.0004"/>
      </geometry>
    </visual>
    <collision>
      <geometry>
        <mesh filename="stl/foot.stl" scale="0.0004 0.0004 0.0004"/>
      </geometry>
    </collision>
    <inertial>
      <origin rpy="0 0 0" xyz="0.0 0.0 0.0"/>
      <mass value="0.5"/>
      <inertia ixx="0.02" ixy="0" ixz="0" iyy="0.02" iyz="0" izz="0.002"/>
    </inertial>
  </link>
  <joint name="leg2_foot_joint" type="revolute">
    <parent link="leg2_calf"/>
    <child link="leg2_foot"/>
    <origin rpy="0 0 0" xyz="0.0 0.0 0.32"/>
    <axis xyz="1 0 0"/>
    <limit effort="100.0" lower="-2.0" upper="2.0" velocity="10.0"/>
  </joint>
  <link name="leg3_lap">
    <visual>
      <geometry>
        <mesh filename="stl/lap.stl" scale="0.0004 0.0004 0.0004"/>
      </geometry>
    </visual>
    <collision>
      <geometry>
        <mesh filename="stl/lap.stl" scale="0.0004 0.0004 0.0004"/>
      </geometry>
    </collision>
    <inertial>
      <origin rpy="0 0 0" xyz="0.0 0.0 0.0002"/>
      <mass value="1.2"/>
      <inertia ixx="0.08" ixy="0" ixz="0" iyy="0.08" iyz="0" izz="0.01"/>
    </inertial>
  </link>
  <joint name="leg3_lap_joint" type="revolute">
    <parent link="head"/>
    <child link="leg3_lap"/>
    <origin rpy="-1.57 0 -2.513" xyz="0.12944000000000003 -0.17816 0.0"/>
    <axis xyz="1 0 0"/>
    <limit effort="100.0" lower="-0.5" upper="0.5" velocity="10.0"/>
  </joint>
  <link name="leg3_calf">
    <visual>
      <geometry>
        <mesh filename="stl/calf.stl" scale="0.0004 0.0004 0.0004"/>
      </geometry>
    </visual>
    <collision>
      <geometry>
        <mesh filename="stl/calf.stl" scale="0.0004 0.0004 0.0004"/>
      </geometry>
    </collision>
    <inertial>
      <origin rpy="0 0 0" xyz="0.0 0.0 0.00016"/>
      <mass value="0.8"/>
      <inertia ixx="0.04" ixy="0" ixz="0" iyy="0.04" iyz="0" izz="0.005"/>
    </inertial>
  </link>
  <joint name="leg3_calf_joint" type="revolute">
    <parent link="leg3_lap"/>
    <child link="leg3_calf"/>
    <origin rpy="0 0 1.5708" xyz="0.0 0.0 0.4"/>
    <axis xyz="1 0 0"/>
    <limit effort="100.0" lower="-2.0" upper="2.0" velocity="10.0"/>
  </joint>
  <link name="leg3_foot">
    <visual>
      <geometry>
        <mesh filename="stl/foot.stl" scale="0.0004 0.0004 0.0004"/>
      </geometry>
    </visual>
    <collision>
      <geometry>
        <mesh filename="stl/foot.stl" scale="0.0004 0.0004 0.0004"/>
      </geometry>
    </collision>
    <inertial>
      <origin rpy="0 0 0" xyz="0.0 0.0 0.0"/>
      <mass value="0.5"/>
      <inertia ixx="0.02" ixy="0" ixz="0" iyy="0.02" iyz="0" izz="0.002"/>
    </inertial>
  </link>
  <joint name="leg3_foot_joint" type="revolute">
    <parent link="leg3_calf"/>
    <child link="leg3_foot"/>
    <origin rpy="0 0 0" xyz="0.0 0.0 0.32"/>
    <axis xyz="1 0 0"/>
    <limit effort="100.0" lower="-2.0" upper="2.0" velocity="10.0"/>
  </joint>
  <link name="leg4_lap">
    <visual>
      <geometry>
        <mesh filename="stl/lap.stl" scale="0.0004 0.0004 0.0004"/>
      </geometry>
    </visual>
    <collision>
      <geometry>
        <mesh filename="stl/lap.stl" scale="0.0004 0.0004 0.0004"/>
      </geometry>
    </collision>
    <inertial>
      <origin rpy="0 0 0" xyz="0.0 0.0 0.0002"/>
      <mass value="1.2"/>
      <inertia ixx="0.08" ixy="0" ixz="0" iyy="0.08" iyz="0" izz="0.01"/>
    </inertial>
  </link>
  <joint name="leg4_lap_joint" type="revolute">
    <parent link="head"/>
    <child link="leg4_lap"/>
    <origin rpy="-1.57 0 2.513" xyz="-0.12944000000000003 -0.17816 0.0"/>
    <axis xyz="1 0 0"/>
    <limit effort="100.0" lower="-0.5" upper="0.5" velocity="10.0"/>
  </joint>
  <link name="leg4_calf">
    <visual>
      <geometry>
        <mesh filename="stl/calf.stl" scale="0.0004 0.0004 0.0004"/>
      </geometry>
    </visual>
    <collision>
      <geometry>
        <mesh filename="stl/calf.stl" scale="0.0004 0.0004 0.0004"/>
      </geometry>
    </collision>
    <inertial>
      <origin rpy="0 0 0" xyz="0.0 0.0 0.00016"/>
      <mass value="0.8"/>
      <inertia ixx="0.04" ixy="0" ixz="0" iyy="0.04" iyz="0" izz="0.005"/>
    </inertial>
  </link>
  <joint name="leg4_calf_joint" type="revolute">
    <parent link="leg4_lap"/>
    <child link="leg4_calf"/>
    <origin rpy="0 0 1.5708" xyz="0.0 0.0 0.4"/>
    <axis xyz="1 0 0"/>
    <limit effort="100.0" lower="-2.0" upper="2.0" velocity="10.0"/>
  </joint>
  <link name="leg4_foot">
    <visual>
      <geometry>
        <mesh filename="stl/foot.stl" scale="0.0004 0.0004 0.0004"/>
      </geometry>
    </visual>
    <collision>
      <geometry>
        <mesh filename="stl/foot.stl" scale="0.0004 0.0004 0.0004"/>
      </geometry>
    </collision>
    <inertial>
      <origin rpy="0 0 0" xyz="0.0 0.0 0.0"/>
      <mass value="0.5"/>
      <inertia ixx="0.02" ixy="0" ixz="0" iyy="0.02" iyz="0" izz="0.002"/>
    </inertial>
  </link>
  <joint name="leg4_foot_joint" type="revolute">
    <parent link="leg4_calf"/>
    <child link="leg4_foot"/>
    <origin rpy="0 0 0" xyz="0.0 0.0 0.32"/>
    <axis xyz="1 0 0"/>
    <limit effort="100.0" lower="-2.0" upper="2.0" velocity="10.0"/>
  </joint>
  <link name="leg5_lap">
    <visual>
      <geometry>
        <mesh filename="stl/lap.stl" scale="0.0004 0.0004 0.0004"/>
      </geometry>
    </visual>
    <collision>
      <geometry>
        <mesh filename="stl/lap.stl" scale="0.0004 0.0004 0.0004"/>
      </geometry>
    </collision>
    <inertial>
      <origin rpy="0 0 0" xyz="0.0 0.0 0.0002"/>
      <mass value="1.2"/>
      <inertia ixx="0.08" ixy="0" ixz="0" iyy="0.08" iyz="0" izz="0.01"/>
    </inertial>
  </link>
  <joint name="leg5_lap_joint" type="revolute">
    <parent link="head"/>
    <child link="leg5_lap"/>
    <origin rpy="-1.57 0 1.257" xyz="-0.20944000000000002 0.06804 0.0"/>
    <axis xyz="1 0 0"/>
    <limit effort="100.0" lower="-0.5" upper="0.5" velocity="10.0"/>
  </joint>
  <link name="leg5_calf">
    <visual>
      <geometry>
        <mesh filename="stl/calf.stl" scale="0.0004 0.0004 0.0004"/>
      </geometry>
    </visual>
    <collision>
      <geometry>
        <mesh filename="stl/calf.stl" scale="0.0004 0.0004 0.0004"/>
      </geometry>
    </collision>
    <inertial>
      <origin rpy="0 0 0" xyz="0.0 0.0 0.00016"/>
      <mass value="0.8"/>
      <inertia ixx="0.04" ixy="0" ixz="0" iyy="0.04" iyz="0" izz="0.005"/>
    </inertial>
  </link>
  <joint name="leg5_calf_joint" type="revolute">
    <parent link="leg5_lap"/>
    <child link="leg5_calf"/>
    <origin rpy="0 0 1.5708" xyz="0.0 0.0 0.4"/>
    <axis xyz="1 0 0"/>
    <limit effort="100.0" lower="-2.0" upper="2.0" velocity="10.0"/>
  </joint>
  <link name="leg5_foot">
    <visual>
      <geometry>
        <mesh filename="stl/foot.stl" scale="0.0004 0.0004 0.0004"/>
      </geometry>
    </visual>
    <collision>
      <geometry>
        <mesh filename="stl/foot.stl" scale="0.0004 0.0004 0.0004"/>
      </geometry>
    </collision>
    <inertial>
      <origin rpy="0 0 0" xyz="0.0 0.0 0.0"/>
      <mass value="0.5"/>
      <inertia ixx="0.02" ixy="0" ixz="0" iyy="0.02" iyz="0" izz="0.002"/>
    </inertial>
  </link>
  <joint name="leg5_foot_joint" type="revolute">
    <parent link="leg5_calf"/>
    <child link="leg5_foot"/>
    <origin rpy="0 0 0" xyz="0.0 0.0 0.32"/>
    <axis xyz="1 0 0"/>
    <limit effort="100.0" lower="-2.0" upper="2.0" velocity="10.0"/>
  </joint>
</robot>
